<?xml version="1.0" encoding="utf-8"?>
<!-- This URDF was automatically created by SolidWorks to URDF Exporter! Originally created by Stephen Brawner (brawner@gmail.com) 
     Commit Version: 1.6.0-4-g7f85cfe  Build Version: 1.6.7995.38578
     For more information, please see http://wiki.ros.org/sw_urdf_exporter -->
<robot
  name="urdf">
  <link name="world" />
  <joint name="world_to_base" type="fixed">
    <parent link="world" />
    <child link="base_link" />
    <origin xyz="0 0 0" rpy="0 0 0" />
  </joint>
  <link
    name="base_link">
    <inertial>
      <origin
        xyz="7.39464030692487E-37 0.00497518035395604 -1.58261138875238E-18"
        rpy="0 0 0" />
      <mass
        value="0.0668483997410034" />
      <inertia
        ixx="2.2462895846101E-05"
        ixy="-1.98954832894814E-40"
        ixz="6.57847844531489E-21"
        iyy="8.77348785237808E-05"
        iyz="1.53787731656788E-24"
        izz="6.63860403141521E-05" />
    </inertial>
    <visual>
      <origin
        xyz="0 0 0"
        rpy="0 0 0" />
      <geometry>
        <mesh
          filename="package://urdf_sim_6dof/meshes/base_link.STL" />
      </geometry>
      <material
        name="">
        <color
          rgba="0.792156862745098 0.819607843137255 0.933333333333333 1" />
      </material>
    </visual>
    <collision>
      <origin
        xyz="0 0 0"
        rpy="0 0 0" />
      <geometry>
        <mesh
          filename="package://urdf_sim_6dof/meshes/base_link.STL" />
      </geometry>
    </collision>
  </link>
  <link
    name="l1">
    <inertial>
      <origin
        xyz="-4.47233396150271E-19 0.114469851476113 0.000115729332966564"
        rpy="0 0 0" />
      <mass
        value="0.030677018968127" />
      <inertia
        ixx="0.000130209033482256"
        ixy="2.38228016415272E-22"
        ixz="1.35525271560688E-20"
        iyy="7.97058979167308E-07"
        iyz="-3.31045646879452E-07"
        izz="0.000130289941570842" />
    </inertial>
    <visual>
      <origin
        xyz="0 0 0"
        rpy="0 0 0" />
      <geometry>
        <mesh
          filename="package://urdf_sim_6dof/meshes/l1.STL" />
      </geometry>
      <material
        name="">
        <color
          rgba="0.792156862745098 0.819607843137255 0.933333333333333 1" />
      </material>
    </visual>
    <collision>
      <origin
        xyz="0 0 0"
        rpy="0 0 0" />
      <geometry>
        <mesh
          filename="package://urdf_sim_6dof/meshes/l1.STL" />
      </geometry>
    </collision>
  </link>
  <joint
    name="base-l1"
    type="continuous">
    <origin
      xyz="0 0 0.005"
      rpy="1.5708 0 0.4874" />
    <parent
      link="base_link" />
    <child
      link="l1" />
    <axis
      xyz="0 1 0" />
  </joint>
  <link
    name="l2">
    <inertial>
      <origin
        xyz="0.0375252841082667 0 -0.0171079946749473"
        rpy="0 0 0" />
      <mass
        value="0.0156636614480709" />
      <inertia
        ixx="5.42911281558323E-07"
        ixy="1.96538113542599E-21"
        ixz="5.75186236513979E-07"
        iyy="1.36310672485375E-05"
        iyz="0"
        izz="1.36646758150697E-05" />
    </inertial>
    <visual>
      <origin
        xyz="0 0 0"
        rpy="0 0 0" />
      <geometry>
        <mesh
          filename="package://urdf_sim_6dof/meshes/l2.STL" />
      </geometry>
      <material
        name="">
        <color
          rgba="0.792156862745098 0.819607843137255 0.933333333333333 1" />
      </material>
    </visual>
    <collision>
      <origin
        xyz="0 0 0"
        rpy="0 0 0" />
      <geometry>
        <mesh
          filename="package://urdf_sim_6dof/meshes/l2.STL" />
      </geometry>
    </collision>
  </link>
  <joint
    name="l1-l2"
    type="continuous">
    <origin
      xyz="0 0.20772 0"
      rpy="0 0 -0.1298" />
    <parent
      link="l1" />
    <child
      link="l2" />
    <axis
      xyz="0 0 1" />
  </joint>
  <link
    name="l3">
    <inertial>
      <origin
        xyz="0.0375252841082671 1.38777878078145E-16 0.0035909270505925"
        rpy="0 0 0" />
      <mass
        value="0.0156636614480709" />
      <inertia
        ixx="5.42911281558326E-07"
        ixy="-4.24839962607235E-21"
        ixz="5.75186236513974E-07"
        iyy="1.36310672485375E-05"
        iyz="1.05879118406788E-22"
        izz="1.36646758150697E-05" />
    </inertial>
    <visual>
      <origin
        xyz="0 0 0"
        rpy="0 0 0" />
      <geometry>
        <mesh
          filename="package://urdf_sim_6dof/meshes/l3.STL" />
      </geometry>
      <material
        name="">
        <color
          rgba="0.792156862745098 0.819607843137255 0.933333333333333 1" />
      </material>
    </visual>
    <collision>
      <origin
        xyz="0 0 0"
        rpy="0 0 0" />
      <geometry>
        <mesh
          filename="package://urdf_sim_6dof/meshes/l3.STL" />
      </geometry>
    </collision>
  </link>
  <joint
    name="l2-l3"
    type="continuous">
    <origin
      xyz="0.083998 0 0"
      rpy="3.1416 0 -0.009783" />
    <parent
      link="l2" />
    <child
      link="l3" />
    <axis
      xyz="0 0 1" />
  </joint>
  <link
    name="l4">
    <inertial>
      <origin
        xyz="0.011900648780722 5.27355936696949E-16 -0.0124070198973897"
        rpy="0 0 0" />
      <mass
        value="0.00749999999999999" />
      <inertia
        ixx="2.3483991734469E-07"
        ixy="4.6859781701129E-22"
        ixz="8.51956560055316E-08"
        iyy="1.63279009857261E-06"
        iyz="5.9557004103818E-23"
        izz="1.67920018122792E-06" />
    </inertial>
    <visual>
      <origin
        xyz="0 0 0"
        rpy="0 0 0" />
      <geometry>
        <mesh
          filename="package://urdf_sim_6dof/meshes/l4.STL" />
      </geometry>
      <material
        name="">
        <color
          rgba="0.792156862745098 0.819607843137255 0.933333333333333 1" />
      </material>
    </visual>
    <collision>
      <origin
        xyz="0 0 0"
        rpy="0 0 0" />
      <geometry>
        <mesh
          filename="package://urdf_sim_6dof/meshes/l4.STL" />
      </geometry>
    </collision>
  </link>
  <joint
    name="l3-l4"
    type="continuous">
    <origin
      xyz="0.083998 0 0"
      rpy="3.1416 0 0.019524" />
    <parent
      link="l3" />
    <child
      link="l4" />
    <axis
      xyz="0 0 1" />
  </joint>
  <link
    name="l5">
    <inertial>
      <origin
        xyz="0.0119006487807222 -3.60822483003176E-16 0.00329190182814997"
        rpy="0 0 0" />
      <mass
        value="0.00750000000000001" />
      <inertia
        ixx="2.34839917344691E-07"
        ixy="5.39321759384574E-22"
        ixz="8.51956560055317E-08"
        iyy="1.63279009857262E-06"
        iyz="3.97046694025453E-23"
        izz="1.67920018122793E-06" />
    </inertial>
    <visual>
      <origin
        xyz="0 0 0"
        rpy="0 0 0" />
      <geometry>
        <mesh
          filename="package://urdf_sim_6dof/meshes/l5.STL" />
      </geometry>
      <material
        name="">
        <color
          rgba="0.792156862745098 0.819607843137255 0.933333333333333 1" />
      </material>
    </visual>
    <collision>
      <origin
        xyz="0 0 0"
        rpy="0 0 0" />
      <geometry>
        <mesh
          filename="package://urdf_sim_6dof/meshes/l5.STL" />
      </geometry>
    </collision>
  </link>
  <joint
    name="l4-l5"
    type="continuous">
    <origin
      xyz="0.027548 0 0"
      rpy="-3.1416 0 -0.026883" />
    <parent
      link="l4" />
    <child
      link="l5" />
    <axis
      xyz="0 0 1" />
  </joint>
  <link
    name="l6">
    <inertial>
      <origin
        xyz="0.0119006487807223 4.16333634234434E-16 -0.0124070198973874"
        rpy="0 0 0" />
      <mass
        value="0.0075" />
      <inertia
        ixx="2.34839917344691E-07"
        ixy="-1.46514365998455E-21"
        ixz="8.51956560055324E-08"
        iyy="1.63279009857262E-06"
        iyz="5.29395592033938E-23"
        izz="1.67920018122793E-06" />
    </inertial>
    <visual>
      <origin
        xyz="0 0 0"
        rpy="0 0 0" />
      <geometry>
        <mesh
          filename="package://urdf_sim_6dof/meshes/l6.STL" />
      </geometry>
      <material
        name="">
        <color
          rgba="0.792156862745098 0.819607843137255 0.933333333333333 1" />
      </material>
    </visual>
    <collision>
      <origin
        xyz="0 0 0"
        rpy="0 0 0" />
      <geometry>
        <mesh
          filename="package://urdf_sim_6dof/meshes/l6.STL" />
      </geometry>
    </collision>
  </link>
  <joint
    name="l5-l6"
    type="continuous">
    <origin
      xyz="0.027548 0 0"
      rpy="-3.1416 0 -0.0078705" />
    <parent
      link="l5" />
    <child
      link="l6" />
    <axis
      xyz="0 0 1" />
  </joint>
</robot>